Traceback (most recent call last):
  File "C:\Users\zerom\miniconda3\envs\group_project\lib\site-packages\jupyter_cache\executors\utils.py", line 58, in single_nb_execution
    executenb(
  File "C:\Users\zerom\miniconda3\envs\group_project\lib\site-packages\nbclient\client.py", line 1305, in execute
    return NotebookClient(nb=nb, resources=resources, km=km, **kwargs).execute()
  File "C:\Users\zerom\miniconda3\envs\group_project\lib\site-packages\jupyter_core\utils\__init__.py", line 173, in wrapped
    return loop.run_until_complete(inner)
  File "C:\Users\zerom\miniconda3\envs\group_project\lib\asyncio\base_events.py", line 641, in run_until_complete
    return future.result()
  File "C:\Users\zerom\miniconda3\envs\group_project\lib\site-packages\nbclient\client.py", line 705, in async_execute
    await self.async_execute_cell(
  File "C:\Users\zerom\miniconda3\envs\group_project\lib\site-packages\nbclient\client.py", line 1058, in async_execute_cell
    await self._check_raise_for_error(cell, cell_index, exec_reply)
  File "C:\Users\zerom\miniconda3\envs\group_project\lib\site-packages\nbclient\client.py", line 914, in _check_raise_for_error
    raise CellExecutionError.from_cell_and_msg(cell, exec_reply_content)
nbclient.exceptions.CellExecutionError: An error occurred while executing the following cell:
------------------

df_combined = pd.read_csv("../data/raw/winequality.csv")

lr_feature_importance_df = pd.read_csv(
    "../results/tables/logistic_regression_feature_importance.csv")
glue("lr_feature_importance_df", lr_feature_importance_df, display=False)  

lr_test_score_df = pd.read_csv(
    "../results/tables/logistic_regression_test_score.csv")
score_value = model_cv_results_df.loc[0, 'test_score']
rounded_score = round(score_value, 4)
final_score = rounded_score
glue("final_test_score", final_score)

model_cv_results_df = pd.read_csv("../results/tables/model_cv_results.csv")
model_cv_results_df.drop(model_cv_results_df.columns[[1, 2]], axis=1, inplace=True)
glue("model_cv_results_df", model_cv_results_df, display=False)                               
------------------


[1;31m---------------------------------------------------------------------------[0m
[1;31mNameError[0m                                 Traceback (most recent call last)
Cell [1;32mIn[2], line 9[0m
[0;32m      5[0m glue([38;5;124m"[39m[38;5;124mlr_feature_importance_df[39m[38;5;124m"[39m, lr_feature_importance_df, display[38;5;241m=[39m[38;5;28;01mFalse[39;00m)  
[0;32m      7[0m lr_test_score_df [38;5;241m=[39m pd[38;5;241m.[39mread_csv(
[0;32m      8[0m     [38;5;124m"[39m[38;5;124m../results/tables/logistic_regression_test_score.csv[39m[38;5;124m"[39m)
[1;32m----> 9[0m score_value [38;5;241m=[39m [43mmodel_cv_results_df[49m[38;5;241m.[39mloc[[38;5;241m0[39m, [38;5;124m'[39m[38;5;124mtest_score[39m[38;5;124m'[39m]
[0;32m     10[0m rounded_score [38;5;241m=[39m [38;5;28mround[39m(score_value, [38;5;241m4[39m)
[0;32m     11[0m final_score [38;5;241m=[39m rounded_score

[1;31mNameError[0m: name 'model_cv_results_df' is not defined

